Workbook

Sheet README
A1: SCORE-01 Scoring Workbook
A2: Purpose | B2: One workbook holds every score the study produces: model calibration, the four Phase 2 audits and the Phase 4 human reviews. Phase 3 was not run, so no re-audit sheet exists. Phase 5 reads its comparisons from the Summary sheet and from Model vs human, under the rules fixed in 74_ANL-01_Analysis_Plan_v1.0.docx.
A3: How to use | B3: Enter scores only in the yellow cells. Black cells carry formulas and are not edited. One sheet per audit; findings go in the findings block beneath the scores.
A4: Scoring rule | B4: Requirement-area score = coverage x 0.35 + accuracy x 0.25 + proportionality x 0.20 + enforceability x 0.20. Policy score = mean of the four areas. Round only at these two points.
A5: Source of truth | B5: The rubric is 21_RUB-01_Evaluation_Rubric_and_Scoring_Guide_v8.1.docx. Where this workbook and the rubric differ, the rubric governs.
A6: Example | B6: The Calibration sheet carries one filled example row (greyed) showing the expected format. It reproduces the Extract 1 figures printed at RUB-01 D.9, so that the row reconciles with the reference score of 47 rather than contradicting it. It is illustration, not data.

Sheet Calibration
A1: Rater | B1: Extract | C1: Coverage | D1: Accuracy | E1: Proportionality | F1: Enforceability | G1: Area score | H1: Reference | I1: Difference | J1: Date | K1: Notes
A2: EXAMPLE (illustration) | B2: 1 | C2: 13 | D2: 90 | E2: 70 | F2: 30 | G2: =IF(COUNT(C2:F2)=4,ROUND(C2*0.35+D2*0.25+E2*0.2+F2*0.2,0),"") | H2: 47 | I2: =IF(G2="","",G2-H2) | J2: 2026-08-18 | K2: Illustration only. These are the Extract 1 figures printed at RUB-01 D.9, which give an area score of 47 and so reconcile with the reference in column H. No rater entered this row.
A3: ChatGPT | B3: 1 | C3: 13 | D3: 90 | E3: 55 | F3: 30 | G3: =IF(COUNT(C3:F3)=4,ROUND(C3*0.35+D3*0.25+E3*0.2+F3*0.2,0),"") | H3: =IF(B3="1",47,73) | I3: =IF(G3="","",G3-H3) | J3: 22 Aug 2026 | K3: Re-run against RUB-01 v8.1. Coverage 13 and accuracy 90 match the reference exactly, as does enforceability at 30; proportionality was entered at 55 against a reference of 70, and that single band step accounts for the whole of the 3-point shortfall, the area score being 44 against 47.
A4: ChatGPT | B4: 2 | C4: 46 | D4: 90 | E4: 75 | F4: 90 | G4: =IF(COUNT(C4:F4)=4,ROUND(C4*0.35+D4*0.25+E4*0.2+F4*0.2,0),"") | H4: =IF(B4="1",47,73) | I4: =IF(G4="","",G4-H4) | J4: 22 Aug 2026 | K4: Re-run against RUB-01 v8.1. Coverage 46 and accuracy 90 match the reference exactly. Proportionality at 75 sits below the reference of 90 and enforceability at 90 sits above the reference of 80, so the two largely offset and the area score is 72 against 73.
A5: Grok | B5: 1 | C5: 13 | D5: 90 | E5: 90 | F5: 30 | G5: =IF(COUNT(C5:F5)=4,ROUND(C5*0.35+D5*0.25+E5*0.2+F5*0.2,0),"") | H5: =IF(B5="1",47,73) | I5: =IF(G5="","",G5-H5) | J5: 22 Aug 2026 | K5: Re-run against RUB-01 v8.1. Coverage 13, accuracy 90 and enforceability 30 all match the reference exactly; proportionality at 90 sits one band above the reference of 70, giving an area score of 51 against 47.
A6: Grok | B6: 2 | C6: 47 | D6: 90 | E6: 70 | F6: 70 | G6: =IF(COUNT(C6:F6)=4,ROUND(C6*0.35+D6*0.25+E6*0.2+F6*0.2,0),"") | H6: =IF(B6="1",47,73) | I6: =IF(G6="","",G6-H6) | J6: 22 Aug 2026 | K6: Re-run against RUB-01 v8.1. Coverage 47 against a reference of 46, a difference of one checklist point on a denominator of 72, being 24 applicable sub-requirements at three points each; accuracy 90 matches. Proportionality at 70 and enforceability at 70 both sit one band below the reference values of 90 and 80, giving an area score of 67 against 73.
A7: R1 | B7: 1 | C7: 13 | D7: 90 | E7: 65 | F7: 25 | G7: =IF(COUNT(C7:F7)=4,ROUND(C7*0.35+D7*0.25+E7*0.2+F7*0.2,0),"") | H7: =IF(B7="1",47,73) | I7: =IF(G7="","",G7-H7) | J7: 22 Aug 2026 | K7: Phase 4 reviewer calibration, RUB-01 v8.1
A8: R1 | B8: 2 | C8: 46 | D8: 90 | E8: 90 | F8: 75 | G8: =IF(COUNT(C8:F8)=4,ROUND(C8*0.35+D8*0.25+E8*0.2+F8*0.2,0),"") | H8: =IF(B8="1",47,73) | I8: =IF(G8="","",G8-H8) | J8: 22 Aug 2026 | K8: Phase 4 reviewer calibration, RUB-01 v8.1
A9: R2 | B9: 1 | C9: 11 | D9: 90 | E9: 70 | F9: 30 | G9: =IF(COUNT(C9:F9)=4,ROUND(C9*0.35+D9*0.25+E9*0.2+F9*0.2,0),"") | H9: =IF(B9="1",47,73) | I9: =IF(G9="","",G9-H9) | J9: 22 Aug 2026 | K9: Phase 4 reviewer calibration, RUB-01 v8.1
A10: R2 | B10: 2 | C10: 46 | D10: 90 | E10: 90 | F10: 80 | G10: =IF(COUNT(C10:F10)=4,ROUND(C10*0.35+D10*0.25+E10*0.2+F10*0.2,0),"") | H10: =IF(B10="1",47,73) | I10: =IF(G10="","",G10-H10) | J10: 22 Aug 2026 | K10: Phase 4 reviewer calibration, RUB-01 v8.1
A11: R3 | B11: 1 | C11: 13 | D11: 90 | E11: 65 | F11: 30 | G11: =IF(COUNT(C11:F11)=4,ROUND(C11*0.35+D11*0.25+E11*0.2+F11*0.2,0),"") | H11: =IF(B11="1",47,73) | I11: =IF(G11="","",G11-H11) | J11: 22 Aug 2026 | K11: Phase 4 reviewer calibration, RUB-01 v8.1
A12: R3 | B12: 2 | C12: 46 | D12: 90 | E12: 90 | F12: 80 | G12: =IF(COUNT(C12:F12)=4,ROUND(C12*0.35+D12*0.25+E12*0.2+F12*0.2,0),"") | H12: =IF(B12="1",47,73) | I12: =IF(G12="","",G12-H12) | J12: 22 Aug 2026 | K12: Phase 4 reviewer calibration, RUB-01 v8.1

Sheet A(P1a)
A1: Audit A(P1a): Grok audits policy P1a
A2: Scores (enter from the audit output; yellow cells only)
A3: Requirement area | B3: Checklist total | C3: Coverage | D3: Accuracy | E3: Proportionality | F3: Enforceability | G3: Area score
A4: Requirement 7 | B4: 25 | C4: 93 | D4: 95 | E4: 90 | F4: 75 | G4: =IF(COUNT(C4:F4)=4,ROUND(C4*0.35+D4*0.25+E4*0.2+F4*0.2,0),"")
A5: Requirement 8 | B5: 68 | C5: 94 | D5: 95 | E5: 85 | F5: 70 | G5: =IF(COUNT(C5:F5)=4,ROUND(C5*0.35+D5*0.25+E5*0.2+F5*0.2,0),"")
A6: Requirement 10 | B6: 24 | C6: 89 | D6: 95 | E6: 80 | F6: 70 | G6: =IF(COUNT(C6:F6)=4,ROUND(C6*0.35+D6*0.25+E6*0.2+F6*0.2,0),"")
A7: Requirement 12 | B7: 80 | C7: 89 | D7: 95 | E7: 75 | F7: 65 | G7: =IF(COUNT(C7:F7)=4,ROUND(C7*0.35+D7*0.25+E7*0.2+F7*0.2,0),"")
A8: Policy-level score | G8: =IF(COUNT(G4:G7)=4,ROUND(AVERAGE(G4:G7),0),"")
A10: Findings (one row per finding; Tag: T/A/L, both allowed; Severity: Critical/Major/Minor)
A11: Sub-requirement | B11: Finding | C11: Tag | D11: Severity | E11: Requirement area
A12: 7.2.4 | B12: user/third-party account reviews every six months with management acknowledgement): present but weakly enforceable because no named owner or evidence/record format is specified beyond a general statement. | C12: A | E12: Requirement 7
A13: 7.2.5.1 / 8.6.3 / 10.4.2.1 / 12.10.4.1 | B13: targeted risk analyses for periodic reviews and frequencies): required and described, yet no actual analyses exist or are referenced; the policy only mandates their future creation. | C13: A | E13: Requirement 7
A14: 8.2.5 / 8.2.6 | B14: immediate revocation on termination; disable inactive accounts ≤90 days): stated, but the organisation currently has no automatic de-provisioning and performs SaaS removal manually; the policy does not close this operational gap. | C14: T, A | E14: Requirement 8
A15: 8.2.8 | B15: 15-minute idle re-authentication): stated for all in-scope sessions, including SaaS, yet the order-management platform currently has no timeout while a tab remains open; the policy does not require remediation of that configuration. | C15: T | E15: Requirement 8
A16: 8.3.6 | B16: minimum 12-character passwords): correctly requires change from the current 10-character setting, but does not set a completion deadline or owner. | C16: T | E16: Requirement 8
A17: 8.4.1–8.4.3 | B17: MFA for all non-console CDE access and remote access): correctly expands beyond the current AWS-console and collaboration-suite enforcement, but provides no implementation owner or target date. | C17: T | E17: Requirement 8
A18: 10.4.1 | B18: daily review of security events, CHD/SAD logs, critical components and security-function logs): stated, including outside office hours, yet current practice is shared-mailbox alerts only 08:00–18:00 weekdays and no 24/7 coverage; the policy does not prescribe how the daily obligation will be met. | C18: T, A | E18: Requirement 10
A19: 10.5.1 | B19: 12-month retention with 3 months immediately available): correctly requires archival beyond the current 90-day SIEM retention, but again lacks owner and timeline. | C19: T | E19: Requirement 10
A20: 12.1.3 / 12.1.4 | B20: roles defined and acknowledged; formal executive assignment): CTO is named, Information Security Manager is named, yet job descriptions still omit security responsibilities and no acknowledgement process is detailed. | C20: A | E20: Requirement 12
A21: 12.3.3 | B21: cryptographic inventory and annual review): required, yet the organisation currently tracks certificates only in a spreadsheet and has no algorithm/protocol inventory; the policy does not compel creation of the missing inventory. | C21: T, A | E21: Requirement 12
A22: 12.6.3 | B22: training upon hire + annually + acknowledgement + multiple methods + 100 % coverage): stated, but current completion is only 78 % and no role-specific training for dispute handlers or administrators is required. | C22: A | E22: Requirement 12
A23: 12.8.1–12.8.5 | B23: TPSP register, written agreements with security acknowledgements, due diligence, annual compliance monitoring, responsibility matrix): all mandated, yet none currently exist; the policy does not set creation deadlines. | C23: A | E23: Requirement 12
... A25: 12.7.1 | B25: No explicit coverage of 12.7.1 screening mechanics beyond the high-level statement (minor). | C25: A | E25: Requirement 12

Sheet A(P1b)
A1: Audit A(P1b): Grok audits policy P1b
A2: Scores (enter from the audit output; yellow cells only)
A3: Requirement area | B3: Checklist total | C3: Coverage | D3: Accuracy | E3: Proportionality | F3: Enforceability | G3: Area score
A4: Requirement 7 | B4: 26 | C4: 96 | D4: 95 | E4: 90 | F4: 85 | G4: =IF(COUNT(C4:F4)=4,ROUND(C4*0.35+D4*0.25+E4*0.2+F4*0.2,0),"")
A5: Requirement 8 | B5: 66 | C5: 92 | D5: 95 | E5: 85 | F5: 80 | G5: =IF(COUNT(C5:F5)=4,ROUND(C5*0.35+D5*0.25+E5*0.2+F5*0.2,0),"")
A6: Requirement 10 | B6: 24 | C6: 89 | D6: 95 | E6: 85 | F6: 75 | G6: =IF(COUNT(C6:F6)=4,ROUND(C6*0.35+D6*0.25+E6*0.2+F6*0.2,0),"")
A7: Requirement 12 | B7: 78 | C7: 87 | D7: 95 | E7: 85 | F7: 75 | G7: =IF(COUNT(C7:F7)=4,ROUND(C7*0.35+D7*0.25+E7*0.2+F7*0.2,0),"")
A8: Policy-level score | G8: =IF(COUNT(G4:G7)=4,ROUND(AVERAGE(G4:G7),0),"")
A10: Findings (one row per finding; Tag: T/A/L, both allowed; Severity: Critical/Major/Minor)
A11: Sub-requirement | B11: Finding | C11: Tag | D11: Severity | E11: Requirement area
A12: 7.2.5.1 / 8.6.3 / 10.4.2.1 / 12.10.4.1 | B12: TRA required but no completed TRA register or examples exist in the organisation context; policy states the obligation without evidence of performance | C12: A | E12: Requirement 7
A13: 8.2.8 | B13: Session timeout stated as required (>15 min) but organisation currently has 60-min AWS and indefinite order-management sessions; remediation is only “shall be remediated” without owner/date | C13: T | E13: Requirement 8
A14: 8.3.6 / 8.3.9 | B14: Current identity-provider minimum is 10 characters and 90-day expiry; policy correctly requires 12 characters and addresses the single-factor case, but the increase and any MFA-based exception remain unimplemented | C14: T | E14: Requirement 8
A15: 8.4.1–8.4.3 | B15: MFA currently enforced only on AWS console and collaboration suite; policy correctly expands the requirement but technical enforcement on order-management, PSP portal and other CDE-impacting paths is still absent | C15: T | E15: Requirement 8
A16: 8.2.5 / 8.2.6 | B16: Immediate revocation and 90-day inactivity stated; organisation still relies on manual SaaS de-provisioning with no automatic process | C16: T, A | E16: Requirement 8
A17: 10.4.1 / 10.5.1 | B17: Daily review and 12-month retention stated; SIEM currently retains only 90 days searchable and no offline archive exists; order-management admin log not forwarded | C17: T | E17: Requirement 10
A18: 10.4.1 | B18: High-severity alerts currently limited to working-hours mailbox; policy requires 24/7 reachability but no on-call rota or technical routing is in place | C18: T, A | E18: Requirement 10
A19: 12.1.1–12.1.4 / 12.6.3 | B19: Policy itself is new; prior template policies had no owner, approval signature or 12-month review evidence; current training completion is 78 % | C19: A | E19: Requirement 12
A20: 12.3.1 / 12.3.3 / 12.3.4 | B20: TRA, cryptographic inventory and technology review obligations stated; organisation currently has none of these artefacts | C20: A | E20: Requirement 12
A21: 12.5.1 / 12.5.2 | B21: Scope inventory and annual validation required; no formal inventory or data-flow diagrams currently maintained | C21: A | E21: Requirement 12
A22: 12.8.1–12.8.5 | B22: Full TPSP programme required; organisation has no register, no written security acknowledgements, no due-diligence process and no responsibility matrix | C22: A | E22: Requirement 12
A23: 12.10.1–12.10.7 | B23: Complete IRP required; organisation currently has no written incident-response plan, no 24/7 contacts, no tested notification path to acquirer and no PAN-discovery procedure | C23: A | E23: Requirement 12
A24: 12.7.1 | B24: Screening required for CDE access; no evidence of current pre-employment screening process | C24: A | E24: Requirement 12
B25: Legislative intersection (UK GDPR 72-hour notification, retention schedules, Dublin transfer documentation): addressed in policy but no internal procedure or records exist | C25: L

Sheet A(P2a)
A1: Audit A(P2a): ChatGPT audits policy P2a
A2: Scores (enter from the audit output; yellow cells only)
A3: Requirement area | B3: Checklist total | C3: Coverage | D3: Accuracy | E3: Proportionality | F3: Enforceability | G3: Area score
A4: Requirement 7 | B4: 18 | C4: 67 | D4: 90 | E4: 75 | F4: 55 | G4: =IF(COUNT(C4:F4)=4,ROUND(C4*0.35+D4*0.25+E4*0.2+F4*0.2,0),"")
A5: Requirement 8 | B5: 48 | C5: 67 | D5: 90 | E5: 70 | F5: 60 | G5: =IF(COUNT(C5:F5)=4,ROUND(C5*0.35+D5*0.25+E5*0.2+F5*0.2,0),"")
A6: Requirement 10 | B6: 18 | C6: 67 | D6: 90 | E6: 55 | F6: 55 | G6: =IF(COUNT(C6:F6)=4,ROUND(C6*0.35+D6*0.25+E6*0.2+F6*0.2,0),"")
A7: Requirement 12 | B7: 59 | C7: 66 | D7: 90 | E7: 55 | F7: 45 | G7: =IF(COUNT(C7:F7)=4,ROUND(C7*0.35+D7*0.25+E7*0.2+F7*0.2,0),"")
A8: Policy-level score | G8: =IF(COUNT(G4:G7)=4,ROUND(AVERAGE(G4:G7),0),"")
A10: Findings (one row per finding; Tag: T/A/L, both allowed; Severity: Critical/Major/Minor)
A11: Sub-requirement | B11: Finding | C11: Tag | D11: Severity | E11: Requirement area
A12: 7.1.2, 8.1.2, 10.1.2, 12.1.3 | B12: The policy repeatedly states that roles and responsibilities “are documented, assigned, and understood” but does not actually identify the operational roles responsible for access administration, authentication, log review, incident response, supplier oversight, training, or risk analysis. | C12: A | E12: Requirement 7
A13: 7.2.1–7.2.5.1 | B13: Access-control obligations are substantively correct but lack named control owners. The Information Security Manager is the document owner, not expressly the person accountable for each provisioning, approval, review and remediation action. | C13: A | E13: Requirement 7
A14: 7.2.4 | B14: Six-monthly access review is stated correctly, but no reviewer, system owner, evidence requirement, escalation route or deadline for removal of inappropriate access is defined. This is material given the three obsolete project groups that still contain members. | C14: A | E14: Requirement 7
A15: 7.2.5.1 | B15: Application/system-account reviews depend on a targeted risk analysis, but NorthPay has no documented targeted risk analysis. Consequently the policy supplies no currently operable review frequency. | C15: A | E15: Requirement 7
A16: 7.2.6 | B16: The policy speaks unconditionally of “repositories of stored cardholder data.” NorthPay does not store full PAN or other CHD on its systems. The provision should either be expressly conditional/not applicable to the present architecture or distinguish unexpected PAN discovery from normal storage. | C16: T, A | E16: Requirement 7
A17: 8.2.4–8.2.6 | B17: Joiner/mover/leaver controls are correctly stated but no lifecycle owner or operating procedure is identified. NorthPay currently removes SaaS access manually and has no automatic de-provisioning, making immediate revocation dependent on an unstated manual process. | C17: T, A | E17: Requirement 8
A18: 8.2.8 | B18: The 15-minute re-authentication rule is correctly reproduced but is not connected to a responsible system owner or enforcement mechanism. Current AWS administrative sessions allow 60 minutes and the order-management session does not time out while its tab remains open. | C18: T | E18: Requirement 8
A19: 8.3.6 | B19: The required 12-character password minimum is correctly stated, but no owner is made responsible for reconciling the policy with the identity provider's existing 10-character minimum. | C19: T | E19: Requirement 8
A20: 8.4.1–8.4.3 | B20: MFA requirements are correctly reproduced but no accountable owner, rollout mechanism or exception/remediation process is identified. NorthPay currently enforces MFA only for AWS and the collaboration suite, despite other systems being capable of impacting the CDE. | C20: T, A | E20: Requirement 8
A21: 8.6.3, 12.3.1 | B21: System/application account password-change frequency is delegated to a targeted risk analysis that does not currently exist, leaving the operative frequency undefined. | C21: T, A | E21: Requirement 8
A22: 10.3.1 | B22: Log-read access is restricted to persons with a job-related need, but the policy neither defines the authorised log-reader roles nor requires periodic review of those permissions. | C22: T, A | E22: Requirement 10
A23: 10.4.1 | B23: Daily review is correctly mandated, but no person or team is responsible for performing and evidencing that review. Current monitoring consists of selected alerts to a mailbox watched only 08:00–18:00 on working days. | C23: T, A | E23: Requirement 10
... A45: Cross-cutting 7.1.1, 8.1.1, 10.1.1, 12.1.1–12.1.2 | B45: P2a declares numerous procedures to be documented, current and “in use,” but the scenario records outdated template policies, no formal review cycle, and several absent processes. The policy contains no implementation/effective-control mechanism for reconciling those declarations with actual practice. This is an enforceability/implementation weakness, not an RUB-01 accuracy defect. | C45: A | E45: Requirement 7

Sheet A(P2b)
A1: Audit A(P2b): ChatGPT audits policy P2b
A2: Scores (enter from the audit output; yellow cells only)
A3: Requirement area | B3: Checklist total | C3: Coverage | D3: Accuracy | E3: Proportionality | F3: Enforceability | G3: Area score
A4: Requirement 7 | B4: 22 | C4: 92 | D4: 100 | E4: 90 | F4: 90 | G4: =IF(COUNT(C4:F4)=4,ROUND(C4*0.35+D4*0.25+E4*0.2+F4*0.2,0),"")
A5: Requirement 8 | B5: 65 | C5: 90 | D5: 100 | E5: 90 | F5: 90 | G5: =IF(COUNT(C5:F5)=4,ROUND(C5*0.35+D5*0.25+E5*0.2+F5*0.2,0),"")
A6: Requirement 10 | B6: 26 | C6: 96 | D6: 100 | E6: 90 | F6: 90 | G6: =IF(COUNT(C6:F6)=4,ROUND(C6*0.35+D6*0.25+E6*0.2+F6*0.2,0),"")
A7: Requirement 12 | B7: 74 | C7: 85 | D7: 100 | E7: 85 | F7: 85 | G7: =IF(COUNT(C7:F7)=4,ROUND(C7*0.35+D7*0.25+E7*0.2+F7*0.2,0),"")
A8: Policy-level score | G8: =IF(COUNT(G4:G7)=4,ROUND(AVERAGE(G4:G7),0),"")
A10: Findings (one row per finding; Tag: T/A/L, both allowed; Severity: Critical/Major/Minor)
A11: Sub-requirement | B11: Finding | C11: Tag | D11: Severity | E11: Requirement area
A12: 8.3.3 | B12: Requirement 8.3.3 — identity verification before authentication-factor changes is absent. Section 4.2 requires approval before modification but never requires verification of the requesting user's identity before an authentication factor is changed. Tag: Technical/Administrative. Severity: Major. | E12: Requirement 8
A13: 12.3.3 and 12.3.4 | B13: Requirements 12.3.3 and 12.3.4 — cryptographic and technology reviews are absent. The policy does not require an annual inventory/review of cipher suites and protocols, monitoring of their continued viability, a response plan for cryptographic weaknesses, or annual review of hardware/software supportability and end-of-life status. This is especially material because NorthPay presently has no cryptographic inventory. Tag: Technical/Administrative. Severity: Major. | E13: Requirement 12
A14: 12.5.2 | B14: Requirement 12.5.2 — annual PCI scoping validation is materially abbreviated. Section 6.4 names data flows, account-data locations, system components, segmentation and third-party connections, but does not expressly require updating data-flow diagrams, checking locations outside the currently defined CDE and backups, documenting justification for out-of-scope environments, or confirming that every identified flow/component/connection is included. Tag: Administrative. Severity: Major. | E14: Requirement 12
A15: 12.2.1 | B15: Requirement 12.2.1 — acceptable-use content is incomplete. Section 6.2 states that acceptable-use rules exist but does not expressly require authorized approval or a maintained list of company-approved hardware and software. Tag: Administrative. Severity: Major. | E15: Requirement 12
A16: 12.6.2 | B16: Requirement 12.6.2 — annual review of the awareness programme itself is not stated. Annual personnel training and annual policy review are specified, but the awareness programme is not expressly required to be reviewed annually and updated for new threats and vulnerabilities. Tag: Administrative. Severity: Major. | E16: Requirement 12
A17: 12.10.5 | B17: Requirement 12.10.5 — incident-monitoring coverage is too generic. “Monitoring and response to alerts from security systems” does not expressly encompass the listed sources, including network security controls, critical-file change detection, payment-page change/tamper detection and unauthorized wireless-access-point detection. Tag: Technical/Administrative. Severity: Major. | E17: Requirement 12
A18: 8.6.3 | B18: Requirement 8.6.3 — system-account password complexity is incomplete. Section 4.11 states the TRA-defined change frequency and change upon suspected compromise, but does not require complexity appropriate to that frequency. Tag: Technical. Severity: Major. | E18: Requirement 8
A19: 8.3.8 | B19: Requirement 8.3.8 — compromise instructions are incomplete. Section 4.12 requires reporting suspected compromise but does not explicitly instruct users to change a password/passphrase where compromise is suspected or known. Tag: Administrative. Severity: Minor. | E19: Requirement 8
A20: 8.2.2 | B20: Requirement 8.2.2 — shared-account exception controls omit an explicit identity-verification step. The policy makes exceptional use attributable to an individual but does not expressly require confirmation of that individual's identity before access is granted. Tag: Technical/Administrative. Severity: Minor. | E20: Requirement 8
A21: 7.1.1, 8.1.1 and 10.1.1 | B21: Requirements 7.1.1, 8.1.1 and 10.1.1 — supporting operational procedures are not demonstrably established. The policy itself is documented and current, but it does not establish that all associated Requirement 7/8/10 operational procedures are documented, current, in use and known to affected parties. Tag: Administrative. Severity: Minor. | E21: Requirement 7
A22: 7.2.5.1 | B22: Requirement 7.2.5.1 — remediation of inappropriate application/system-account access is implicit rather than explicit. Section 3.4 requires review and management acknowledgement but omits the express requirement that inappropriate application/system-account access identified by that review be addressed. Tag: Administrative/Technical. Severity: Minor. | E22: Requirement 7
A23: 8.2.8 | B23: Requirement 8.2.8 — policy and operating environment conflict. Section 4.5 correctly mandates re-authentication after 15 minutes, but the scenario says order-management sessions currently remain active while the browser tab is open and administrative console sessions time out after 60 minutes. The policy is compliant wording but is not presently enforceable across the stated environment. Tag: Technical. Severity: Major. | E23: Requirement 8
... A33: 12.2.1 | B33: Requirement 12.2.1 — personal-device restriction is not currently technically enforced. Section 6.2 says conditional access enforces the restriction, whereas the scenario states it is presently enforced only by convention. Tag: Technical. Severity: Major. | E33: Requirement 12
B34: UK GDPR retention governance remains incomplete. Section 5.7 promises documented retention schedules within three months, but the scenario has no defined retention periods for support tickets, marketing lists or log data. The forward commitment is useful but does not itself establish the required governance. Tag: Legislative/Administrative. Severity: Minor.
B35: UK GDPR/card-compromise notification integration is not presently operational. Section 6.8 correctly calls for mapped ICO and PCI/acquirer paths, but the scenario confirms no internal procedure capable of reliably meeting the statutory 72-hour process and no tested relationship between the two notification paths. Tag: Legislative/Administrative. Severity: Major.

Sheet Summary
A1: Phase 2 summary (fills itself from the audit sheets)
A2: Audit | B2: Auditor | C2: Policy | D2: Req 7 | E2: Req 8 | F2: Req 10 | G2: Req 12 | H2: Policy score
A3: A(P1a) | B3: Grok | C3: P1a | D3: ='A(P1a)'!G4 | E3: ='A(P1a)'!G5 | F3: ='A(P1a)'!G6 | G3: ='A(P1a)'!G7 | H3: ='A(P1a)'!G8
A4: A(P1b) | B4: Grok | C4: P1b | D4: ='A(P1b)'!G4 | E4: ='A(P1b)'!G5 | F4: ='A(P1b)'!G6 | G4: ='A(P1b)'!G7 | H4: ='A(P1b)'!G8
A5: A(P2a) | B5: ChatGPT | C5: P2a | D5: ='A(P2a)'!G4 | E5: ='A(P2a)'!G5 | F5: ='A(P2a)'!G6 | G5: ='A(P2a)'!G7 | H5: ='A(P2a)'!G8
A6: A(P2b) | B6: ChatGPT | C6: P2b | D6: ='A(P2b)'!G4 | E6: ='A(P2b)'!G5 | F6: ='A(P2b)'!G6 | G6: ='A(P2b)'!G7 | H6: ='A(P2b)'!G8

Sheet Run details
A1: Run | B1: Model | C1: Build | D1: Interface | E1: Date and time (BST) | F1: Prompt file used | G1: Output file | H1: Refusal or truncation | I1: Non-default settings
A2: Calibration, ChatGPT | B2: ChatGPT | C2: 5.6 SoL | D2: Web UI | E2: 22/08/2026 - 01:05 | F2: PROMPT-CAL_Calibration_ASSEMBLED_2026-08-22.txt | G2: CAL_ChatGPT_PromptCAL_2026-08-22.txt | H2: None | I2: None
A3: Calibration, Grok | B3: Grok | C3: Grok 4.5 | D3: Web UI | E3: 22/08/2026 - 01:10 | F3: PROMPT-CAL_Calibration_ASSEMBLED_2026-08-22.txt | G3: CAL_Grok_PromptCAL_2026-08-22.txt | H3: None | I3: None
A4: A(P1a) | B4: Grok | C4: Grok 4.5 | D4: Web UI | E4: 22/08/2026 - 02:10 | F4: PROMPT-C_Audit-of-P1a_ASSEMBLED_2026-08-22.txt | G4: A(P1a)_Grok_PromptC_2026-08-22.txt | H4: None | I4: None
A5: A(P1b) | B5: Grok | C5: Grok 4.5 | D5: Web UI | E5: 22/08/2026 - 02:15 | F5: PROMPT-C_Audit-of-P1b_ASSEMBLED_2026-08-22.txt | G5: A(P1b)_Grok_PromptC_2026-08-22.txt | H5: None | I5: None
A6: A(P2a) | B6: ChatGPT | C6: 5.6 SoL | D6: Web UI | E6: 22/08/2026 - 02:20 | F6: PROMPT-C_Audit-of-P2a_ASSEMBLED_2026-08-22.txt | G6: A(P2a)_ChatGPT_PromptC_2026-08-22.txt | H6: None | I6: None
A7: A(P2b) | B7: ChatGPT | C7: 5.6 SoL | D7: Web UI | E7: 22/08/2026 - 02:30 | F7: PROMPT-C_Audit-of-P2b_ASSEMBLED_2026-08-22.txt | G7: A(P2b)_ChatGPT_PromptC_2026-08-22.txt | H7: None | I7: None

Sheet Human scores
A1: Phase 4 human reviewer scores (RESP-01 v4.0, RUB-01 v8.1). Entered from the returned _v2 forms.
A2: Reviewers are identified by code only. The code-to-name mapping is held outside this workbook and is not reproduced in the dissertation.
A3: Reviewer | B3: Policy | C3: Requirement area | D3: Req 8 checklist points | E3: Coverage | F3: Accuracy | G3: Proportionality | H3: Enforceability | I3: Area score
A4: R1 | B4: P1a | C4: Requirement 7 | E4: 96 | F4: 90 | G4: 90 | H4: 65 | I4: =IF(COUNT(E4:H4)=4,ROUND(E4*0.35+F4*0.25+G4*0.2+H4*0.2,0),"")
A5: R1 | B5: P1a | C5: Requirement 8 | D5: 71 | E5: 99 | F5: 90 | G5: 90 | H5: 65 | I5: =IF(COUNT(E5:H5)=4,ROUND(E5*0.35+F5*0.25+G5*0.2+H5*0.2,0),"")
A6: R1 | B6: P1a | C6: Requirement 10 | E6: 96 | F6: 90 | G6: 85 | H6: 65 | I6: =IF(COUNT(E6:H6)=4,ROUND(E6*0.35+F6*0.25+G6*0.2+H6*0.2,0),"")
A7: R1 | B7: P1a | C7: Requirement 12 | E7: 99 | F7: 90 | G7: 90 | H7: 70 | I7: =IF(COUNT(E7:H7)=4,ROUND(E7*0.35+F7*0.25+G7*0.2+H7*0.2,0),"")
A8: R1 | B8: P1b | C8: Requirement 7 | E8: 96 | F8: 90 | G8: 95 | H8: 75 | I8: =IF(COUNT(E8:H8)=4,ROUND(E8*0.35+F8*0.25+G8*0.2+H8*0.2,0),"")
A9: R1 | B9: P1b | C9: Requirement 8 | D9: 68 | E9: 94 | F9: 90 | G9: 95 | H9: 70 | I9: =IF(COUNT(E9:H9)=4,ROUND(E9*0.35+F9*0.25+G9*0.2+H9*0.2,0),"")
A10: R1 | B10: P1b | C10: Requirement 10 | E10: 100 | F10: 90 | G10: 95 | H10: 80 | I10: =IF(COUNT(E10:H10)=4,ROUND(E10*0.35+F10*0.25+G10*0.2+H10*0.2,0),"")
A11: R1 | B11: P1b | C11: Requirement 12 | E11: 97 | F11: 90 | G11: 95 | H11: 80 | I11: =IF(COUNT(E11:H11)=4,ROUND(E11*0.35+F11*0.25+G11*0.2+H11*0.2,0),"")
A12: R1 | B12: P2a | C12: Requirement 7 | E12: 93 | F12: 90 | G12: 60 | H12: 50 | I12: =IF(COUNT(E12:H12)=4,ROUND(E12*0.35+F12*0.25+G12*0.2+H12*0.2,0),"")
A13: R1 | B13: P2a | C13: Requirement 8 | D13: 70 | E13: 97 | F13: 90 | G13: 65 | H13: 55 | I13: =IF(COUNT(E13:H13)=4,ROUND(E13*0.35+F13*0.25+G13*0.2+H13*0.2,0),"")
A14: R1 | B14: P2a | C14: Requirement 10 | E14: 93 | F14: 90 | G14: 60 | H14: 55 | I14: =IF(COUNT(E14:H14)=4,ROUND(E14*0.35+F14*0.25+G14*0.2+H14*0.2,0),"")
A15: R1 | B15: P2a | C15: Requirement 12 | E15: 96 | F15: 90 | G15: 60 | H15: 50 | I15: =IF(COUNT(E15:H15)=4,ROUND(E15*0.35+F15*0.25+G15*0.2+H15*0.2,0),"")
A16: R1 | B16: P2b | C16: Requirement 7 | E16: 89 | F16: 90 | G16: 95 | H16: 75 | I16: =IF(COUNT(E16:H16)=4,ROUND(E16*0.35+F16*0.25+G16*0.2+H16*0.2,0),"")
A17: R1 | B17: P2b | C17: Requirement 8 | D17: 63 | E17: 88 | F17: 90 | G17: 95 | H17: 65 | I17: =IF(COUNT(E17:H17)=4,ROUND(E17*0.35+F17*0.25+G17*0.2+H17*0.2,0),"")
A18: R1 | B18: P2b | C18: Requirement 10 | E18: 93 | F18: 90 | G18: 90 | H18: 70 | I18: =IF(COUNT(E18:H18)=4,ROUND(E18*0.35+F18*0.25+G18*0.2+H18*0.2,0),"")
A19: R1 | B19: P2b | C19: Requirement 12 | E19: 80 | F19: 90 | G19: 85 | H19: 75 | I19: =IF(COUNT(E19:H19)=4,ROUND(E19*0.35+F19*0.25+G19*0.2+H19*0.2,0),"")
A20: R2 | B20: P1a | C20: Requirement 7 | E20: 96 | F20: 90 | G20: 90 | H20: 70 | I20: =IF(COUNT(E20:H20)=4,ROUND(E20*0.35+F20*0.25+G20*0.2+H20*0.2,0),"")
A21: R2 | B21: P1a | C21: Requirement 8 | D21: 71 | E21: 99 | F21: 90 | G21: 90 | H21: 75 | I21: =IF(COUNT(E21:H21)=4,ROUND(E21*0.35+F21*0.25+G21*0.2+H21*0.2,0),"")
A22: R2 | B22: P1a | C22: Requirement 10 | E22: 96 | F22: 90 | G22: 85 | H22: 70 | I22: =IF(COUNT(E22:H22)=4,ROUND(E22*0.35+F22*0.25+G22*0.2+H22*0.2,0),"")
A23: R2 | B23: P1a | C23: Requirement 12 | E23: 99 | F23: 90 | G23: 85 | H23: 70 | I23: =IF(COUNT(E23:H23)=4,ROUND(E23*0.35+F23*0.25+G23*0.2+H23*0.2,0),"")
A24: R2 | B24: P1b | C24: Requirement 7 | E24: 96 | F24: 90 | G24: 90 | H24: 80 | I24: =IF(COUNT(E24:H24)=4,ROUND(E24*0.35+F24*0.25+G24*0.2+H24*0.2,0),"")
A25: R2 | B25: P1b | C25: Requirement 8 | D25: 68 | E25: 94 | F25: 90 | G25: 95 | H25: 80 | I25: =IF(COUNT(E25:H25)=4,ROUND(E25*0.35+F25*0.25+G25*0.2+H25*0.2,0),"")
A26: R2 | B26: P1b | C26: Requirement 10 | E26: 100 | F26: 90 | G26: 95 | H26: 80 | I26: =IF(COUNT(E26:H26)=4,ROUND(E26*0.35+F26*0.25+G26*0.2+H26*0.2,0),"")
A27: R2 | B27: P1b | C27: Requirement 12 | E27: 99 | F27: 90 | G27: 95 | H27: 80 | I27: =IF(COUNT(E27:H27)=4,ROUND(E27*0.35+F27*0.25+G27*0.2+H27*0.2,0),"")
A28: R2 | B28: P2a | C28: Requirement 7 | E28: 96 | F28: 90 | G28: 70 | H28: 55 | I28: =IF(COUNT(E28:H28)=4,ROUND(E28*0.35+F28*0.25+G28*0.2+H28*0.2,0),"")
A29: R2 | B29: P2a | C29: Requirement 8 | D29: 71 | E29: 99 | F29: 90 | G29: 70 | H29: 55 | I29: =IF(COUNT(E29:H29)=4,ROUND(E29*0.35+F29*0.25+G29*0.2+H29*0.2,0),"")
A30: R2 | B30: P2a | C30: Requirement 10 | E30: 96 | F30: 90 | G30: 65 | H30: 55 | I30: =IF(COUNT(E30:H30)=4,ROUND(E30*0.35+F30*0.25+G30*0.2+H30*0.2,0),"")
A31: R2 | B31: P2a | C31: Requirement 12 | E31: 98 | F31: 90 | G31: 65 | H31: 50 | I31: =IF(COUNT(E31:H31)=4,ROUND(E31*0.35+F31*0.25+G31*0.2+H31*0.2,0),"")
A32: R2 | B32: P2b | C32: Requirement 7 | E32: 89 | F32: 90 | G32: 70 | H32: 75 | I32: =IF(COUNT(E32:H32)=4,ROUND(E32*0.35+F32*0.25+G32*0.2+H32*0.2,0),"")
A33: R2 | B33: P2b | C33: Requirement 8 | D33: 64 | E33: 89 | F33: 90 | G33: 75 | H33: 70 | I33: =IF(COUNT(E33:H33)=4,ROUND(E33*0.35+F33*0.25+G33*0.2+H33*0.2,0),"")
A34: R2 | B34: P2b | C34: Requirement 10 | E34: 93 | F34: 90 | G34: 75 | H34: 70 | I34: =IF(COUNT(E34:H34)=4,ROUND(E34*0.35+F34*0.25+G34*0.2+H34*0.2,0),"")
A35: R2 | B35: P2b | C35: Requirement 12 | E35: 80 | F35: 90 | G35: 70 | H35: 75 | I35: =IF(COUNT(E35:H35)=4,ROUND(E35*0.35+F35*0.25+G35*0.2+H35*0.2,0),"")
A36: R3 | B36: P1a | C36: Requirement 7 | E36: 100 | F36: 90 | G36: 90 | H36: 65 | I36: =IF(COUNT(E36:H36)=4,ROUND(E36*0.35+F36*0.25+G36*0.2+H36*0.2,0),"")
A37: R3 | B37: P1a | C37: Requirement 8 | D37: 70 | E37: 97 | F37: 90 | G37: 80 | H37: 75 | I37: =IF(COUNT(E37:H37)=4,ROUND(E37*0.35+F37*0.25+G37*0.2+H37*0.2,0),"")
A38: R3 | B38: P1a | C38: Requirement 10 | E38: 100 | F38: 90 | G38: 70 | H38: 65 | I38: =IF(COUNT(E38:H38)=4,ROUND(E38*0.35+F38*0.25+G38*0.2+H38*0.2,0),"")
A39: R3 | B39: P1a | C39: Requirement 12 | E39: 100 | F39: 90 | G39: 85 | H39: 65 | I39: =IF(COUNT(E39:H39)=4,ROUND(E39*0.35+F39*0.25+G39*0.2+H39*0.2,0),"")
A40: R3 | B40: P1b | C40: Requirement 7 | E40: 96 | F40: 90 | G40: 95 | H40: 75 | I40: =IF(COUNT(E40:H40)=4,ROUND(E40*0.35+F40*0.25+G40*0.2+H40*0.2,0),"")
...

Sheet Human findings
A1: Phase 4 reviewer findings, transcribed verbatim from the returned forms.
A2: Reviewers are identified by code only. The code-to-name mapping is held outside this workbook and is not reproduced in the dissertation.
A3: Reviewer | B3: Policy | C3: Requirement area | D3: Sub-requirement | E3: What is missing, wrong or unenforceable | F3: Tag | G3: Severity
A4: R1 | B4: P1a | C4: Requirement 7 | D4: 7.1.2 | E4: Clause 1.3 states that operational responsibilities "shall be documented, assigned and communicated", which defers the assignment instead of making it. No role is named for any Requirement 7 activity, and "communicated" is weaker than the standard's "understood". | F4: A | G4: Minor
A5: R1 | B5: P1a | C5: Requirement 7 | D5: 7.2.3 | E5: Clause 2.2 requires approval by "authorized personnel" and nowhere states who holds that authority. Whether a given approval was validly given is therefore not testable. | F5: A | G5: Minor
A6: R1 | B6: P1a | C6: Requirement 7 | D6: 7.2.4 | E6: Clause 2.3 states the 6-month interval and the 4 review elements entirely in the passive, so no role is required to perform the review, and none is required to address its exceptions or to hold the management acknowledgement. No owner is named. | F6: A | G6: Minor
A7: R1 | B7: P1a | C7: Requirement 7 | D7: 7.2.5.1 | E7: The review frequency is deferred to a targeted risk analysis which clause 5.3 also does no more than promise. Until that analysis exists, no testable interval binds the review of application and system accounts. | F7: A | G7: Minor
A8: R1 | B8: P1a | C8: Requirement 7 | D8: 7.2.6 | E8: Although the condition is defensible for this environment, the control is conditional on a repository existing ("Where a repository of stored cardholder data exists within scope"), and no role is made responsible for determining that one has come into existence. | F8: A | G8: Minor
A9: R1 | B9: P1a | C9: Requirement 8 | D9: 8.1.2 | E9: As at 7.1.2. Clause 1.3 carries the same wording, "shall be documented, assigned and communicated", and no role owns any Requirement 8 activity. The standard's "understood" is not stated. | F9: A | G9: Minor
A10: R1 | B10: P1a | C10: Requirement 8 | D10: 8.2.2 | E10: Clause 3.2 requires "explicit management approval" without stating which manager holds it, and limits use to "the time required" without setting a maximum or a review point. No approver is named and no ceiling is set. | F10: A | G10: Minor
A11: R1 | B11: P1a | C11: Requirement 8 | D11: 8.2.8 | E11: Clause 3.5 applies the 15-minute rule "where Requirement 8.2.8 applies". The qualifier is self-referential, so the set of in-scope sessions is left undetermined, and although the order-management platform is described, it is not named as bound by the clause. | F11: T | G11: Minor
A12: R1 | B12: P1a | C12: Requirement 8 | D12: 8.3.4 | E12: Clause 3.7 sets lockout at "no more than 10 invalid authentication attempts", where the identity provider is already stricter at 6. The systems the clause binds are not named and the stricter existing setting is not preserved, so the clause reads as licence to relax it. | F12: T | G12: Minor
A13: R1 | B13: P1a | C13: Requirement 8 | D13: 8.6.2 | E13: Although the prohibition on hard-coded credentials is stated in full, the deployment credentials held as repository secrets are not addressed anywhere, so whether that arrangement satisfies 3.12 or breaches it is left to inference. | F13: T | G13: Minor
A14: R1 | B14: P1a | C14: Requirement 8 | D14: 8.3.8 | E14: Clause 3.9 states what the guidance must address, and then assigns no author and names no distribution point, and nothing requires the audience to be tested, so "documented and communicated to users" is not evidenced from the policy alone. | F14: A | G14: Minor
... A254: R3 | B254: P2b | C254: Requirement 12 | D254: 12.3.1 | E254: Clause 6.3 omits the element requiring an updated analysis where the annual review determines one is needed, and owner and first-production date for the analyses are both unstated. | F254: A | G254: Minor

Sheet Model vs human
A1: Requirement-area scores: the model auditor against the three human reviewers, same policy, same area.
A3: Policy | B3: Requirement area | C3: Model auditor | D3: Model score | E3: R1 | F3: R2 | G3: R3 | H3: Human mean | I3: Model minus human mean
A4: P1a | B4: Requirement 7 | C4: A(P1a) Grok | D4: 89 | E4: ='Human scores'!I4 | F4: ='Human scores'!I20 | G4: ='Human scores'!I36 | H4: =ROUND(AVERAGE(E4:G4),1) | I4: =D4-H4
A5: P1a | B5: Requirement 8 | C5: A(P1a) Grok | D5: 88 | E5: ='Human scores'!I5 | F5: ='Human scores'!I21 | G5: ='Human scores'!I37 | H5: =ROUND(AVERAGE(E5:G5),1) | I5: =D5-H5
A6: P1a | B6: Requirement 10 | C6: A(P1a) Grok | D6: 85 | E6: ='Human scores'!I6 | F6: ='Human scores'!I22 | G6: ='Human scores'!I38 | H6: =ROUND(AVERAGE(E6:G6),1) | I6: =D6-H6
A7: P1a | B7: Requirement 12 | C7: A(P1a) Grok | D7: 83 | E7: ='Human scores'!I7 | F7: ='Human scores'!I23 | G7: ='Human scores'!I39 | H7: =ROUND(AVERAGE(E7:G7),1) | I7: =D7-H7
A8: P1b | B8: Requirement 7 | C8: A(P1b) Grok | D8: 92 | E8: ='Human scores'!I8 | F8: ='Human scores'!I24 | G8: ='Human scores'!I40 | H8: =ROUND(AVERAGE(E8:G8),1) | I8: =D8-H8
A9: P1b | B9: Requirement 8 | C9: A(P1b) Grok | D9: 89 | E9: ='Human scores'!I9 | F9: ='Human scores'!I25 | G9: ='Human scores'!I41 | H9: =ROUND(AVERAGE(E9:G9),1) | I9: =D9-H9
A10: P1b | B10: Requirement 10 | C10: A(P1b) Grok | D10: 87 | E10: ='Human scores'!I10 | F10: ='Human scores'!I26 | G10: ='Human scores'!I42 | H10: =ROUND(AVERAGE(E10:G10),1) | I10: =D10-H10
A11: P1b | B11: Requirement 12 | C11: A(P1b) Grok | D11: 86 | E11: ='Human scores'!I11 | F11: ='Human scores'!I27 | G11: ='Human scores'!I43 | H11: =ROUND(AVERAGE(E11:G11),1) | I11: =D11-H11
A12: P2a | B12: Requirement 7 | C12: A(P2a) ChatGPT | D12: 72 | E12: ='Human scores'!I12 | F12: ='Human scores'!I28 | G12: ='Human scores'!I44 | H12: =ROUND(AVERAGE(E12:G12),1) | I12: =D12-H12
A13: P2a | B13: Requirement 8 | C13: A(P2a) ChatGPT | D13: 72 | E13: ='Human scores'!I13 | F13: ='Human scores'!I29 | G13: ='Human scores'!I45 | H13: =ROUND(AVERAGE(E13:G13),1) | I13: =D13-H13
A14: P2a | B14: Requirement 10 | C14: A(P2a) ChatGPT | D14: 68 | E14: ='Human scores'!I14 | F14: ='Human scores'!I30 | G14: ='Human scores'!I46 | H14: =ROUND(AVERAGE(E14:G14),1) | I14: =D14-H14
A15: P2a | B15: Requirement 12 | C15: A(P2a) ChatGPT | D15: 66 | E15: ='Human scores'!I15 | F15: ='Human scores'!I31 | G15: ='Human scores'!I47 | H15: =ROUND(AVERAGE(E15:G15),1) | I15: =D15-H15
... A19: P2b | B19: Requirement 12 | C19: A(P2b) ChatGPT | D19: 89 | E19: ='Human scores'!I19 | F19: ='Human scores'!I35 | G19: ='Human scores'!I51 | H19: =ROUND(AVERAGE(E19:G19),1) | I19: =D19-H19
